Workbook

Sheet Contents
B2: Databook entries
B3: facility | C3: List the study site / facility. Example Code Name format: facility_1, Display Name format: Facility 1
B4: emission sources | C4: List the emission sources. Example Code Name format: emission_1, Display Name format: Emission 1
B5: emission data | C5: The first row and column of this table get updated automatically. Fill the table with the emission data for each facility.
B7: Program book entries
B8: interventions | C8: List the mitigation interventions. Example Code Name format: intervention_1, Display Name format: Intervention 1
B9: exclusions | C9: List any combinations of interventions that should not appear together in a scenario
B10: emission targets | C10: The first row and column of this table get updated automatically. Fill the table with 'y' where an intervention targets a specific emission source. Leave other cells blank.
B11: effect sizes | C11: The first row and column of this table get updated automatically. Specify the effect sizes of the interventions (if an intervention reduces emissions from a specific source by 80%, then effect size = 0.80).
B12: implementation costs | C12: The first row and column of this table get updated automatically. Specify the total cost of implementing the interventions to reach full coverage for each facility.
B13: maintenance costs | C13: The first row and column of this table get updated automatically. Specify the total (yearly) cost of maintaining the interventions at full coverage for each facility.

Sheet facility
A1: Code Name | B1: Display Name
A2: Mt_Darwin | B2: Mt Darwin District Hospital

Sheet emission sources
A1: Code Name | B1: Display Name
A2: Grid_Electricity | B2: Grid Electricity ( Excluding Heating & Lighting)
A3: Lighting | B3: Lighting
A4: Heating | B4: Heating
A5: Building_Energy | B5: Building energy
A6: Vehicle_Fuel_Owned | B6: Vehicle Fuel (Owned Vehicles)
A7: Business_Travel | B7: Business travel (Taxi, Car hires, Train, Air travel, Local bus)
A8: Anaesthetic_Gases | B8: Anaesthetic gases
A9: Refrigeration_Gases | B9: Refrigerants
A10: Medical_Inhalers | B10: Inhalers
A11: Waste_Management | B11: Waste
A12: Contactor_logistics | B12: Contractor Logistics

Sheet emission data
A1: facilities | B1: =IF('emission sources'!$A2<>"",'emission sources'!$A2,"") -> Grid_Electricity | C1: =IF('emission sources'!$A3<>"",'emission sources'!$A3,"") -> Lighting | D1: =IF('emission sources'!$A4<>"",'emission sources'!$A4,"") -> Heating | E1: =IF('emission sources'!$A5<>"",'emission sources'!$A5,"") -> Building_Energy | F1: =IF('emission sources'!$A6<>"",'emission sources'!$A6,"") -> Vehicle_Fuel_Owned | G1: =IF('emission sources'!$A7<>"",'emission sources'!$A7,"") -> Business_Travel | H1: =IF('emission sources'!$A8<>"",'emission sources'!$A8,"") -> Anaesthetic_Gases | I1: =IF('emission sources'!$A9<>"",'emission sources'!$A9,"") -> Refrigeration_Gases | J1: =IF('emission sources'!$A10<>"",'emission sources'!$A10,"") -> Medical_Inhalers | K1: =IF('emission sources'!$A11<>"",'emission sources'!$A11,"") -> Waste_Management | L1: =IF('emission sources'!$A12<>"",'emission sources'!$A12,"") -> Contactor_logistics | M1: =IF('emission sources'!$A13<>"",'emission sources'!$A13,"") | N1: =IF('emission sources'!$A14<>"",'emission sources'!$A14,"") | O1: =IF('emission sources'!$A15<>"",'emission sources'!$A15,"") | P1: =IF('emission sources'!$A16<>"",'emission sources'!$A16,"") | Q1: =IF('emission sources'!$A17<>"",'emission sources'!$A17,"") | R1: =IF('emission sources'!$A18<>"",'emission sources'!$A18,"") | S1: =IF('emission sources'!$A19<>"",'emission sources'!$A19,"") | T1: =IF('emission sources'!$A20<>"",'emission sources'!$A20,"") | U1: =IF('emission sources'!$A21<>"",'emission sources'!$A21,"") | V1: =IF('emission sources'!$A22<>"",'emission sources'!$A22,"") | W1: =IF('emission sources'!$A23<>"",'emission sources'!$A23,"") | X1: =IF('emission sources'!$A24<>"",'emission sources'!$A24,"") | Y1: =IF('emission sources'!$A25<>"",'emission sources'!$A25,"") | Z1: =IF('emission sources'!$A26<>"",'emission sources'!$A26,"") | AA1: =IF('emission sources'!$A27<>"",'emission sources'!$A27,"") | AB1: =IF('emission sources'!$A28<>"",'emission sources'!$A28,"") | AC1: =IF('emission sources'!$A29<>"",'emission sources'!$A29,"") | AD1: =IF('emission sources'!$A30<>"",'emission sources'!$A30,"") | AE1: =IF('emission sources'!$A31<>"",'emission sources'!$A31,"") | AF1: =IF('emission sources'!$A32<>"",'emission sources'!$A32,"") | AG1: =IF('emission sources'!$A33<>"",'emission sources'!$A33,"") | AH1: =IF('emission sources'!$A34<>"",'emission sources'!$A34,"") | AI1: =IF('emission sources'!$A35<>"",'emission sources'!$A35,"") | AJ1: =IF('emission sources'!$A36<>"",'emission sources'!$A36,"") | AK1: =IF('emission sources'!$A37<>"",'emission sources'!$A37,"") | AL1: =IF('emission sources'!$A38<>"",'emission sources'!$A38,"") | AM1: =IF('emission sources'!$A39<>"",'emission sources'!$A39,"") | AN1: =IF('emission sources'!$A40<>"",'emission sources'!$A40,"") | AO1: =IF('emission sources'!$A41<>"",'emission sources'!$A41,"") | AP1: =IF('emission sources'!$A42<>"",'emission sources'!$A42,"") | AQ1: =IF('emission sources'!$A43<>"",'emission sources'!$A43,"") | AR1: =IF('emission sources'!$A44<>"",'emission sources'!$A44,"") | AS1: =IF('emission sources'!$A45<>"",'emission sources'!$A45,"") | AT1: =IF('emission sources'!$A46<>"",'emission sources'!$A46,"") | AU1: =IF('emission sources'!$A47<>"",'emission sources'!$A47,"") | AV1: =IF('emission sources'!$A48<>"",'emission sources'!$A48,"") | AW1: =IF('emission sources'!$A49<>"",'emission sources'!$A49,"") | AX1: =IF('emission sources'!$A50<>"",'emission sources'!$A50,"") | AY1: =IF('emission sources'!$A51<>"",'emission sources'!$A51,"") | AZ1: =IF('emission sources'!$A52<>"",'emission sources'!$A52,"") | BA1: =IF('emission sources'!$A53<>"",'emission sources'!$A53,"") | BB1: =IF('emission sources'!$A54<>"",'emission sources'!$A54,"") | BC1: =IF('emission sources'!$A55<>"",'emission sources'!$A55,"") | BD1: =IF('emission sources'!$A56<>"",'emission sources'!$A56,"") | BE1: =IF('emission sources'!$A57<>"",'emission sources'!$A57,"") | BF1: =IF('emission sources'!$A58<>"",'emission sources'!$A58,"") | BG1: =IF('emission sources'!$A59<>"",'emission sources'!$A59,"") | BH1: =IF('emission sources'!$A60<>"",'emission sources'!$A60,"") | BI1: =IF('emission sources'!$A61<>"",'emission sources'!$A61,"") | BJ1: =IF('emission sources'!$A62<>"",'emission sources'!$A62,"") | BK1: =IF('emission sources'!$A63<>"",'emission sources'!$A63,"") | BL1: =IF('emission sources'!$A64<>"",'emission sources'!$A64,"") | BM1: =IF('emission sources'!$A65<>"",'emission sources'!$A65,"") | BN1: =IF('emission sources'!$A66<>"",'emission sources'!$A66,"") | BO1: =IF('emission sources'!$A67<>"",'emission sources'!$A67,"") | BP1: =IF('emission sources'!$A68<>"",'emission sources'!$A68,"") | BQ1: =IF('emission sources'!$A69<>"",'emission sources'!$A69,"") | BR1: =IF('emission sources'!$A70<>"",'emission sources'!$A70,"") | BS1: =IF('emission sources'!$A71<>"",'emission sources'!$A71,"") | BT1: =IF('emission sources'!$A72<>"",'emission sources'!$A72,"") | BU1: =IF('emission sources'!$A73<>"",'emission sources'!$A73,"") | BV1: =IF('emission sources'!$A74<>"",'emission sources'!$A74,"") | BW1: =IF('emission sources'!$A75<>"",'emission sources'!$A75,"") | BX1: =IF('emission sources'!$A76<>"",'emission sources'!$A76,"") | BY1: =IF('emission sources'!$A77<>"",'emission sources'!$A77,"") | BZ1: =IF('emission sources'!$A78<>"",'emission sources'!$A78,"") | CA1: =IF('emission sources'!$A79<>"",'emission sources'!$A79,"") | CB1: =IF('emission sources'!$A80<>"",'emission sources'!$A80,"") | CC1: =IF('emission sources'!$A81<>"",'emission sources'!$A81,"") | CD1: =IF('emission sources'!$A82<>"",'emission sources'!$A82,"") | CE1: =IF('emission sources'!$A83<>"",'emission sources'!$A83,"") | CF1: =IF('emission sources'!$A84<>"",'emission sources'!$A84,"") | CG1: =IF('emission sources'!$A85<>"",'emission sources'!$A85,"") | CH1: =IF('emission sources'!$A86<>"",'emission sources'!$A86,"") | CI1: =IF('emission sources'!$A87<>"",'emission sources'!$A87,"") | CJ1: =IF('emission sources'!$A88<>"",'emission sources'!$A88,"") | CK1: =IF('emission sources'!$A89<>"",'emission sources'!$A89,"") | CL1: =IF('emission sources'!$A90<>"",'emission sources'!$A90,"") | CM1: =IF('emission sources'!$A91<>"",'emission sources'!$A91,"") | CN1: =IF('emission sources'!$A92<>"",'emission sources'!$A92,"") | CO1: =IF('emission sources'!$A93<>"",'emission sources'!$A93,"") | CP1: =IF('emission sources'!$A94<>"",'emission sources'!$A94,"") | CQ1: =IF('emission sources'!$A95<>"",'emission sources'!$A95,"") | CR1: =IF('emission sources'!$A96<>"",'emission sources'!$A96,"") | CS1: =IF('emission sources'!$A97<>"",'emission sources'!$A97,"") | CT1: =IF('emission sources'!$A98<>"",'emission sources'!$A98,"") | CU1: =IF('emission sources'!$A99<>"",'emission sources'!$A99,"") | CV1: =IF('emission sources'!$A100<>"",'emission sources'!$A100,"") | CW1: =IF('emission sources'!$A101<>"",'emission sources'!$A101,"") | CX1: =IF('emission sources'!$A102<>"",'emission sources'!$A102,"") | CY1: =IF('emission sources'!$A103<>"",'emission sources'!$A103,"") | CZ1: =IF('emission sources'!$A104<>"",'emission sources'!$A104,"") | DA1: =IF('emission sources'!$A105<>"",'emission sources'!$A105,"") | DB1: =IF('emission sources'!$A106<>"",'emission sources'!$A106,"") | DC1: =IF('emission sources'!$A107<>"",'emission sources'!$A107,"") | DD1: =IF('emission sources'!$A108<>"",'emission sources'!$A108,"") | DE1: =IF('emission sources'!$A109<>"",'emission sources'!$A109,"") | DF1: =IF('emission sources'!$A110<>"",'emission sources'!$A110,"") | DG1: =IF('emission sources'!$A111<>"",'emission sources'!$A111,"") | DH1: =IF('emission sources'!$A112<>"",'emission sources'!$A112,"") | DI1: =IF('emission sources'!$A113<>"",'emission sources'!$A113,"") | DJ1: =IF('emission sources'!$A114<>"",'emission sources'!$A114,"") | DK1: =IF('emission sources'!$A115<>"",'emission sources'!$A115,"") | DL1: =IF('emission sources'!$A116<>"",'emission sources'!$A116,"") | DM1: =IF('emission sources'!$A117<>"",'emission sources'!$A117,"") | DN1: =IF('emission sources'!$A118<>"",'emission sources'!$A118,"") | DO1: =IF('emission sources'!$A119<>"",'emission sources'!$A119,"") | DP1: =IF('emission sources'!$A120<>"",'emission sources'!$A120,"") | DQ1: =IF('emission sources'!$A121<>"",'emission sources'!$A121,"") | DR1: =IF('emission sources'!$A122<>"",'emission sources'!$A122,"") | DS1: =IF('emission sources'!$A123<>"",'emission sources'!$A123,"") | DT1: =IF('emission sources'!$A124<>"",'emission sources'!$A124,"") | DU1: =IF('emission sources'!$A125<>"",'emission sources'!$A125,"") | DV1: =IF('emission sources'!$A126<>"",'emission sources'!$A126,"") | DW1: =IF('emission sources'!$A127<>"",'emission sources'!$A127,"") | DX1: =IF('emission sources'!$A128<>"",'emission sources'!$A128,"") | DY1: =IF('emission sources'!$A129<>"",'emission sources'!$A129,"") | DZ1: =IF('emission sources'!$A130<>"",'emission sources'!$A130,"") | EA1: =IF('emission sources'!$A131<>"",'emission sources'!$A131,"") | EB1: =IF('emission sources'!$A132<>"",'emission sources'!$A132,"") | EC1: =IF('emission sources'!$A133<>"",'emission sources'!$A133,"") | ED1: =IF('emission sources'!$A134<>"",'emission sources'!$A134,"") | EE1: =IF('emission sources'!$A135<>"",'emission sources'!$A135,"") | EF1: =IF('emission sources'!$A136<>"",'emission sources'!$A136,"") | EG1: =IF('emission sources'!$A137<>"",'emission sources'!$A137,"") | EH1: =IF('emission sources'!$A138<>"",'emission sources'!$A138,"") | EI1: =IF('emission sources'!$A139<>"",'emission sources'!$A139,"") | EJ1: =IF('emission sources'!$A140<>"",'emission sources'!$A140,"") | EK1: =IF('emission sources'!$A141<>"",'emission sources'!$A141,"") | EL1: =IF('emission sources'!$A142<>"",'emission sources'!$A142,"") | EM1: =IF('emission sources'!$A143<>"",'emission sources'!$A143,"") | EN1: =IF('emission sources'!$A144<>"",'emission sources'!$A144,"") | EO1: =IF('emission sources'!$A145<>"",'emission sources'!$A145,"") | EP1: =IF('emission sources'!$A146<>"",'emission sources'!$A146,"") | EQ1: =IF('emission sources'!$A147<>"",'emission sources'!$A147,"") | ER1: =IF('emission sources'!$A148<>"",'emission sources'!$A148,"") | ES1: =IF('emission sources'!$A149<>"",'emission sources'!$A149,"") | ET1: =IF('emission sources'!$A150<>"",'emission sources'!$A150,"") | EU1: =IF('emission sources'!$A151<>"",'emission sources'!$A151,"") | EV1: =IF('emission sources'!$A152<>"",'emission sources'!$A152,"") | EW1: =IF('emission sources'!$A153<>"",'emission sources'!$A153,"") | EX1: =IF('emission sources'!$A154<>"",'emission sources'!$A154,"") | EY1: =IF('emission sources'!$A155<>"",'emission sources'!$A155,"") | EZ1: =IF('emission sources'!$A156<>"",'emission sources'!$A156,"") | FA1: =IF('emission sources'!$A157<>"",'emission sources'!$A157,"") | FB1: =IF('emission sources'!$A158<>"",'emission sources'!$A158,"") | FC1: =IF('emission sources'!$A159<>"",'emission sources'!$A159,"") | FD1: =IF('emission sources'!$A160<>"",'emission sources'!$A160,"") | FE1: =IF('emission sources'!$A161<>"",'emission sources'!$A161,"") | FF1: =IF('emission sources'!$A162<>"",'emission sources'!$A162,"") | FG1: =IF('emission sources'!$A163<>"",'emission sources'!$A163,"") | FH1: =IF('emission sources'!$A164<>"",'emission sources'!$A164,"") | FI1: =IF('emission sources'!$A165<>"",'emission sources'!$A165,"") | FJ1: =IF('emission sources'!$A166<>"",'emission sources'!$A166,"") | FK1: =IF('emission sources'!$A167<>"",'emission sources'!$A167,"") | FL1: =IF('emission sources'!$A168<>"",'emission sources'!$A168,"") | FM1: =IF('emission sources'!$A169<>"",'emission sources'!$A169,"") | FN1: =IF('emission sources'!$A170<>"",'emission sources'!$A170,"") | FO1: =IF('emission sources'!$A171<>"",'emission sources'!$A171,"") | FP1: =IF('emission sources'!$A172<>"",'emission sources'!$A172,"") | FQ1: =IF('emission sources'!$A173<>"",'emission sources'!$A173,"") | FR1: =IF('emission sources'!$A174<>"",'emission sources'!$A174,"") | FS1: =IF('emission sources'!$A175<>"",'emission sources'!$A175,"") | FT1: =IF('emission sources'!$A176<>"",'emission sources'!$A176,"") | FU1: =IF('emission sources'!$A177<>"",'emission sources'!$A177,"") | FV1: =IF('emission sources'!$A178<>"",'emission sources'!$A178,"") | FW1: =IF('emission sources'!$A179<>"",'emission sources'!$A179,"") | FX1: =IF('emission sources'!$A180<>"",'emission sources'!$A180,"") | FY1: =IF('emission sources'!$A181<>"",'emission sources'!$A181,"") | FZ1: =IF('emission sources'!$A182<>"",'emission sources'!$A182,"") | GA1: =IF('emission sources'!$A183<>"",'emission sources'!$A183,"") | GB1: =IF('emission sources'!$A184<>"",'emission sources'!$A184,"") | GC1: =IF('emission sources'!$A185<>"",'emission sources'!$A185,"") | GD1: =IF('emission sources'!$A186<>"",'emission sources'!$A186,"") | GE1: =IF('emission sources'!$A187<>"",'emission sources'!$A187,"") | GF1: =IF('emission sources'!$A188<>"",'emission sources'!$A188,"") | GG1: =IF('emission sources'!$A189<>"",'emission sources'!$A189,"") | GH1: =IF('emission sources'!$A190<>"",'emission sources'!$A190,"") | GI1: =IF('emission sources'!$A191<>"",'emission sources'!$A191,"") | GJ1: =IF('emission sources'!$A192<>"",'emission sources'!$A192,"") | GK1: =IF('emission sources'!$A193<>"",'emission sources'!$A193,"") | GL1: =IF('emission sources'!$A194<>"",'emission sources'!$A194,"") | GM1: =IF('emission sources'!$A195<>"",'emission sources'!$A195,"") | GN1: =IF('emission sources'!$A196<>"",'emission sources'!$A196,"") | GO1: =IF('emission sources'!$A197<>"",'emission sources'!$A197,"") | GP1: =IF('emission sources'!$A198<>"",'emission sources'!$A198,"") | GQ1: =IF('emission sources'!$A199<>"",'emission sources'!$A199,"") | GR1: =IF('emission sources'!$A200<>"",'emission sources'!$A200,"") | GS1: =IF('emission sources'!$A201<>"",'emission sources'!$A201,"") | GT1: =IF('emission sources'!$A202<>"",'emission sources'!$A202,"") | GU1: =IF('emission sources'!$A203<>"",'emission sources'!$A203,"") | GV1: =IF('emission sources'!$A204<>"",'emission sources'!$A204,"") | GW1: =IF('emission sources'!$A205<>"",'emission sources'!$A205,"") | GX1: =IF('emission sources'!$A206<>"",'emission sources'!$A206,"") | GY1: =IF('emission sources'!$A207<>"",'emission sources'!$A207,"") | GZ1: =IF('emission sources'!$A208<>"",'emission sources'!$A208,"") | HA1: =IF('emission sources'!$A209<>"",'emission sources'!$A209,"") | HB1: =IF('emission sources'!$A210<>"",'emission sources'!$A210,"") | HC1: =IF('emission sources'!$A211<>"",'emission sources'!$A211,"") | HD1: =IF('emission sources'!$A212<>"",'emission sources'!$A212,"") | HE1: =IF('emission sources'!$A213<>"",'emission sources'!$A213,"") | HF1: =IF('emission sources'!$A214<>"",'emission sources'!$A214,"") | HG1: =IF('emission sources'!$A215<>"",'emission sources'!$A215,"") | HH1: =IF('emission sources'!$A216<>"",'emission sources'!$A216,"") | HI1: =IF('emission sources'!$A217<>"",'emission sources'!$A217,"") | HJ1: =IF('emission sources'!$A218<>"",'emission sources'!$A218,"") | HK1: =IF('emission sources'!$A219<>"",'emission sources'!$A219,"") | HL1: =IF('emission sources'!$A220<>"",'emission sources'!$A220,"") | HM1: =IF('emission sources'!$A221<>"",'emission sources'!$A221,"") | HN1: =IF('emission sources'!$A222<>"",'emission sources'!$A222,"") | HO1: =IF('emission sources'!$A223<>"",'emission sources'!$A223,"") | HP1: =IF('emission sources'!$A224<>"",'emission sources'!$A224,"") | HQ1: =IF('emission sources'!$A225<>"",'emission sources'!$A225,"") | HR1: =IF('emission sources'!$A226<>"",'emission sources'!$A226,"") | HS1: =IF('emission sources'!$A227<>"",'emission sources'!$A227,"") | HT1: =IF('emission sources'!$A228<>"",'emission sources'!$A228,"") | HU1: =IF('emission sources'!$A229<>"",'emission sources'!$A229,"") | HV1: =IF('emission sources'!$A230<>"",'emission sources'!$A230,"") | HW1: =IF('emission sources'!$A231<>"",'emission sources'!$A231,"") | HX1: =IF('emission sources'!$A232<>"",'emission sources'!$A232,"") | HY1: =IF('emission sources'!$A233<>"",'emission sources'!$A233,"") | HZ1: =IF('emission sources'!$A234<>"",'emission sources'!$A234,"") | IA1: =IF('emission sources'!$A235<>"",'emission sources'!$A235,"") | IB1: =IF('emission sources'!$A236<>"",'emission sources'!$A236,"") | IC1: =IF('emission sources'!$A237<>"",'emission sources'!$A237,"") | ID1: =IF('emission sources'!$A238<>"",'emission sources'!$A238,"") | IE1: =IF('emission sources'!$A239<>"",'emission sources'!$A239,"") | IF1: =IF('emission sources'!$A240<>"",'emission sources'!$A240,"") | IG1: =IF('emission sources'!$A241<>"",'emission sources'!$A241,"") | IH1: =IF('emission sources'!$A242<>"",'emission sources'!$A242,"") | II1: =IF('emission sources'!$A243<>"",'emission sources'!$A243,"") | IJ1: =IF('emission sources'!$A244<>"",'emission sources'!$A244,"") | IK1: =IF('emission sources'!$A245<>"",'emission sources'!$A245,"") | IL1: =IF('emission sources'!$A246<>"",'emission sources'!$A246,"") | IM1: =IF('emission sources'!$A247<>"",'emission sources'!$A247,"") | IN1: =IF('emission sources'!$A248<>"",'emission sources'!$A248,"") | IO1: =IF('emission sources'!$A249<>"",'emission sources'!$A249,"") | IP1: =IF('emission sources'!$A250<>"",'emission sources'!$A250,"") | IQ1: =IF('emission sources'!$A251<>"",'emission sources'!$A251,"") | IR1: =IF('emission sources'!$A252<>"",'emission sources'!$A252,"") | IS1: =IF('emission sources'!$A253<>"",'emission sources'!$A253,"") | IT1: =IF('emission sources'!$A254<>"",'emission sources'!$A254,"") | IU1: =IF('emission sources'!$A255<>"",'emission sources'!$A255,"") | IV1: =IF('emission sources'!$A256<>"",'emission sources'!$A256,"") | IW1: =IF('emission sources'!$A257<>"",'emission sources'!$A257,"") | IX1: =IF('emission sources'!$A258<>"",'emission sources'!$A258,"") | IY1: =IF('emission sources'!$A259<>"",'emission sources'!$A259,"") | IZ1: =IF('emission sources'!$A260<>"",'emission sources'!$A260,"") | JA1: =IF('emission sources'!$A261<>"",'emission sources'!$A261,"") | JB1: =IF('emission sources'!$A262<>"",'emission sources'!$A262,"") | JC1: =IF('emission sources'!$A263<>"",'emission sources'!$A263,"") | JD1: =IF('emission sources'!$A264<>"",'emission sources'!$A264,"") | JE1: =IF('emission sources'!$A265<>"",'emission sources'!$A265,"") | JF1: =IF('emission sources'!$A266<>"",'emission sources'!$A266,"") | JG1: =IF('emission sources'!$A267<>"",'emission sources'!$A267,"") | JH1: =IF('emission sources'!$A268<>"",'emission sources'!$A268,"") | JI1: =IF('emission sources'!$A269<>"",'emission sources'!$A269,"") | JJ1: =IF('emission sources'!$A270<>"",'emission sources'!$A270,"") | JK1: =IF('emission sources'!$A271<>"",'emission sources'!$A271,"") | JL1: =IF('emission sources'!$A272<>"",'emission sources'!$A272,"") | JM1: =IF('emission sources'!$A273<>"",'emission sources'!$A273,"") | JN1: =IF('emission sources'!$A274<>"",'emission sources'!$A274,"") | JO1: =IF('emission sources'!$A275<>"",'emission sources'!$A275,"") | JP1: =IF('emission sources'!$A276<>"",'emission sources'!$A276,"") | JQ1: =IF('emission sources'!$A277<>"",'emission sources'!$A277,"") | JR1: =IF('emission sources'!$A278<>"",'emission sources'!$A278,"") | JS1: =IF('emission sources'!$A279<>"",'emission sources'!$A279,"") | JT1: =IF('emission sources'!$A280<>"",'emission sources'!$A280,"") | JU1: =IF('emission sources'!$A281<>"",'emission sources'!$A281,"") | JV1: =IF('emission sources'!$A282<>"",'emission sources'!$A282,"") | JW1: =IF('emission sources'!$A283<>"",'emission sources'!$A283,"") | JX1: =IF('emission sources'!$A284<>"",'emission sources'!$A284,"") | JY1: =IF('emission sources'!$A285<>"",'emission sources'!$A285,"") | JZ1: =IF('emission sources'!$A286<>"",'emission sources'!$A286,"") | KA1: =IF('emission sources'!$A287<>"",'emission sources'!$A287,"") | KB1: =IF('emission sources'!$A288<>"",'emission sources'!$A288,"")
A2: =IF(facility!$A2<>"",facility!$A2,"") -> Mt_Darwin | B2: 30926.5 | C2: 8434.5 | D2: 16869 | E2: 8720 | F2: 47900 | G2: 170 | H2: 4130 | I2: 19350 | J2: 4840 | K2: 7460 | L2: 1308
A3: =IF(facility!$A3<>"",facility!$A3,"")
A4: =IF(facility!$A4<>"",facility!$A4,"")
A5: =IF(facility!$A5<>"",facility!$A5,"")
A6: =IF(facility!$A6<>"",facility!$A6,"")
A7: =IF(facility!$A7<>"",facility!$A7,"")
A8: =IF(facility!$A8<>"",facility!$A8,"")
A9: =IF(facility!$A9<>"",facility!$A9,"")
A10: =IF(facility!$A10<>"",facility!$A10,"")
A11: =IF(facility!$A11<>"",facility!$A11,"")
A12: =IF(facility!$A12<>"",facility!$A12,"")
A13: =IF(facility!$A13<>"",facility!$A13,"")
A14: =IF(facility!$A14<>"",facility!$A14,"")
... A19: =IF(facility!$A19<>"",facility!$A19,"")
A20: =IF(facility!$A31<>"",facility!$A31,"")
A21: =IF(facility!$A32<>"",facility!$A32,"") | B21: =IF('emission sources'!$A12<>"",'emission sources'!$A12,"") -> Contactor_logistics
A22: =IF(facility!$A33<>"",facility!$A33,"") | B22: =IF('emission sources'!$A13<>"",'emission sources'!$A13,"")
A23: =IF(facility!$A34<>"",facility!$A34,"") | B23: =IF('emission sources'!$A14<>"",'emission sources'!$A14,"")
A24: =IF(facility!$A35<>"",facility!$A35,"") | B24: =IF('emission sources'!$A15<>"",'emission sources'!$A15,"")
A25: =IF(facility!$A36<>"",facility!$A36,"") | B25: =IF('emission sources'!$A16<>"",'emission sources'!$A16,"")
A26: =IF(facility!$A37<>"",facility!$A37,"") | B26: =IF('emission sources'!$A17<>"",'emission sources'!$A17,"")
A27: =IF(facility!$A38<>"",facility!$A38,"") | B27: =IF('emission sources'!$A18<>"",'emission sources'!$A18,"")
A28: =IF(facility!$A39<>"",facility!$A39,"") | B28: =IF('emission sources'!$A19<>"",'emission sources'!$A19,"")
A29: =IF(facility!$A40<>"",facility!$A40,"") | B29: =IF('emission sources'!$A20<>"",'emission sources'!$A20,"")
A30: =IF(facility!$A41<>"",facility!$A41,"") | B30: =IF('emission sources'!$A21<>"",'emission sources'!$A21,"")
A31: =IF(facility!$A42<>"",facility!$A42,"") | B31: =IF('emission sources'!$A22<>"",'emission sources'!$A22,"")
A32: =IF(facility!$A43<>"",facility!$A43,"") | B32: =IF('emission sources'!$A23<>"",'emission sources'!$A23,"")
... A297: =IF(facility!$A308<>"",facility!$A308,"") | B297: =IF('emission sources'!$A288<>"",'emission sources'!$A288,"")
A298: =IF(facility!$A309<>"",facility!$A309,"")

Sheet interventions
A1: Code Name | B1: Display Name | C1: Additional annual CO2 reduction | D1: Cost co-benefits | E1: Other co-benefits
A2: solar_system1 | B2: Solar system (5Va) | D2: 2199 | E2: Reliable power, lower costs, better cold chain, supports medical equipment.
A3: led_light1 | B3: 35 LED lights (18W) | D3: 161 | E3: Lower energy costs
A4: energy_efficient_fridge1 | B4: 1 Energy efficient large deep fridge | D4: 110 | E4: Prevents spoilage, saves electricity, extends equipment lifespan.
A5: energy_efficient_fridge_multi5 | B5: 5 Energy efficient small upright fridges | D5: 474 | E5: Prevents spoilage, saves electricity, extends equipment lifespan.
A6: laundry_machine | B6: Energy Efficient laundry Machine (10kg) | D6: 71 | E6: Saves water, protects linen, improves infection control.
A7: energy_efficient_ac_multi1 | B7: 1 Energy efficient AC units | D7: 37 | E7: Better air quality, improved comfort, lower power bills.
A8: energy_efficient_ac_multi5 | B8: 5 Energy efficient AC units | D8: 185 | E8: Better air quality, improved comfort, lower power bills.
A9: energy_efficient_ac_multi10 | B9: 10 Energy efficient AC units | D9: 370 | E9: Better air quality, improved comfort, lower power bills.
A10: tree_planting_multi100 | B10: 100 Trees | D10: -500 | E10: Improves air quality, provides shade, boosts mental health.
A11: tree_planting_multi200 | B11: 200 Trees | D11: -1000 | E11: Improves air quality, provides shade, boosts mental health.
A12: waste_segregation | B12: 4 Waste segregation bins | D12: 5670 | E12: Reduces contamination, improves hygiene, saves disposal costs.
A13: staff_training_awareness | B13: Engagement & awareness | D13: 579 | E13: Empowers staff, boosts efficiency, promotes sustainability.

Sheet exclusions
A1: tree_planting_multi100 | B1: tree_planting_multi200

Sheet emission targets
A1: interventions | B1: =IF('emission sources'!$A2<>"",'emission sources'!$A2,"") -> Grid_Electricity | C1: =IF('emission sources'!$A3<>"",'emission sources'!$A3,"") -> Lighting | D1: =IF('emission sources'!$A4<>"",'emission sources'!$A4,"") -> Heating | E1: =IF('emission sources'!$A5<>"",'emission sources'!$A5,"") -> Building_Energy | F1: =IF('emission sources'!$A6<>"",'emission sources'!$A6,"") -> Vehicle_Fuel_Owned | G1: =IF('emission sources'!$A7<>"",'emission sources'!$A7,"") -> Business_Travel | H1: =IF('emission sources'!$A8<>"",'emission sources'!$A8,"") -> Anaesthetic_Gases | I1: =IF('emission sources'!$A9<>"",'emission sources'!$A9,"") -> Refrigeration_Gases | J1: =IF('emission sources'!$A10<>"",'emission sources'!$A10,"") -> Medical_Inhalers | K1: =IF('emission sources'!$A11<>"",'emission sources'!$A11,"") -> Waste_Management | L1: =IF('emission sources'!$A12<>"",'emission sources'!$A12,"") -> Contactor_logistics | M1: =IF('emission sources'!$A13<>"",'emission sources'!$A13,"") | N1: =IF('emission sources'!$A14<>"",'emission sources'!$A14,"") | O1: =IF('emission sources'!$A15<>"",'emission sources'!$A15,"") | P1: =IF('emission sources'!$A16<>"",'emission sources'!$A16,"") | Q1: =IF('emission sources'!$A17<>"",'emission sources'!$A17,"") | R1: =IF('emission sources'!$A18<>"",'emission sources'!$A18,"") | S1: =IF('emission sources'!$A19<>"",'emission sources'!$A19,"") | T1: =IF('emission sources'!$A20<>"",'emission sources'!$A20,"") | U1: =IF('emission sources'!$A21<>"",'emission sources'!$A21,"") | V1: =IF('emission sources'!$A22<>"",'emission sources'!$A22,"") | W1: =IF('emission sources'!$A23<>"",'emission sources'!$A23,"") | X1: =IF('emission sources'!$A24<>"",'emission sources'!$A24,"") | Y1: =IF('emission sources'!$A25<>"",'emission sources'!$A25,"") | Z1: =IF('emission sources'!$A26<>"",'emission sources'!$A26,"") | AA1: =IF('emission sources'!$A27<>"",'emission sources'!$A27,"") | AB1: =IF('emission sources'!$A28<>"",'emission sources'!$A28,"") | AC1: =IF('emission sources'!$A29<>"",'emission sources'!$A29,"") | AD1: =IF('emission sources'!$A30<>"",'emission sources'!$A30,"") | AE1: =IF('emission sources'!$A31<>"",'emission sources'!$A31,"") | AF1: =IF('emission sources'!$A32<>"",'emission sources'!$A32,"") | AG1: =IF('emission sources'!$A33<>"",'emission sources'!$A33,"") | AH1: =IF('emission sources'!$A34<>"",'emission sources'!$A34,"") | AI1: =IF('emission sources'!$A35<>"",'emission sources'!$A35,"") | AJ1: =IF('emission sources'!$A36<>"",'emission sources'!$A36,"") | AK1: =IF('emission sources'!$A37<>"",'emission sources'!$A37,"") | AL1: =IF('emission sources'!$A38<>"",'emission sources'!$A38,"") | AM1: =IF('emission sources'!$A39<>"",'emission sources'!$A39,"") | AN1: =IF('emission sources'!$A40<>"",'emission sources'!$A40,"") | AO1: =IF('emission sources'!$A41<>"",'emission sources'!$A41,"") | AP1: =IF('emission sources'!$A42<>"",'emission sources'!$A42,"") | AQ1: =IF('emission sources'!$A43<>"",'emission sources'!$A43,"") | AR1: =IF('emission sources'!$A44<>"",'emission sources'!$A44,"") | AS1: =IF('emission sources'!$A45<>"",'emission sources'!$A45,"") | AT1: =IF('emission sources'!$A46<>"",'emission sources'!$A46,"") | AU1: =IF('emission sources'!$A47<>"",'emission sources'!$A47,"") | AV1: =IF('emission sources'!$A48<>"",'emission sources'!$A48,"") | AW1: =IF('emission sources'!$A49<>"",'emission sources'!$A49,"") | AX1: =IF('emission sources'!$A50<>"",'emission sources'!$A50,"") | AY1: =IF('emission sources'!$A51<>"",'emission sources'!$A51,"") | AZ1: =IF('emission sources'!$A52<>"",'emission sources'!$A52,"") | BA1: =IF('emission sources'!$A53<>"",'emission sources'!$A53,"") | BB1: =IF('emission sources'!$A54<>"",'emission sources'!$A54,"") | BC1: =IF('emission sources'!$A55<>"",'emission sources'!$A55,"") | BD1: =IF('emission sources'!$A56<>"",'emission sources'!$A56,"") | BE1: =IF('emission sources'!$A57<>"",'emission sources'!$A57,"") | BF1: =IF('emission sources'!$A58<>"",'emission sources'!$A58,"") | BG1: =IF('emission sources'!$A59<>"",'emission sources'!$A59,"") | BH1: =IF('emission sources'!$A60<>"",'emission sources'!$A60,"") | BI1: =IF('emission sources'!$A61<>"",'emission sources'!$A61,"") | BJ1: =IF('emission sources'!$A62<>"",'emission sources'!$A62,"") | BK1: =IF('emission sources'!$A63<>"",'emission sources'!$A63,"") | BL1: =IF('emission sources'!$A64<>"",'emission sources'!$A64,"") | BM1: =IF('emission sources'!$A65<>"",'emission sources'!$A65,"") | BN1: =IF('emission sources'!$A66<>"",'emission sources'!$A66,"") | BO1: =IF('emission sources'!$A67<>"",'emission sources'!$A67,"") | BP1: =IF('emission sources'!$A68<>"",'emission sources'!$A68,"") | BQ1: =IF('emission sources'!$A69<>"",'emission sources'!$A69,"") | BR1: =IF('emission sources'!$A70<>"",'emission sources'!$A70,"") | BS1: =IF('emission sources'!$A71<>"",'emission sources'!$A71,"") | BT1: =IF('emission sources'!$A72<>"",'emission sources'!$A72,"") | BU1: =IF('emission sources'!$A73<>"",'emission sources'!$A73,"") | BV1: =IF('emission sources'!$A74<>"",'emission sources'!$A74,"") | BW1: =IF('emission sources'!$A75<>"",'emission sources'!$A75,"") | BX1: =IF('emission sources'!$A76<>"",'emission sources'!$A76,"") | BY1: =IF('emission sources'!$A77<>"",'emission sources'!$A77,"") | BZ1: =IF('emission sources'!$A78<>"",'emission sources'!$A78,"") | CA1: =IF('emission sources'!$A79<>"",'emission sources'!$A79,"") | CB1: =IF('emission sources'!$A80<>"",'emission sources'!$A80,"") | CC1: =IF('emission sources'!$A81<>"",'emission sources'!$A81,"") | CD1: =IF('emission sources'!$A82<>"",'emission sources'!$A82,"") | CE1: =IF('emission sources'!$A83<>"",'emission sources'!$A83,"") | CF1: =IF('emission sources'!$A84<>"",'emission sources'!$A84,"") | CG1: =IF('emission sources'!$A85<>"",'emission sources'!$A85,"") | CH1: =IF('emission sources'!$A86<>"",'emission sources'!$A86,"") | CI1: =IF('emission sources'!$A87<>"",'emission sources'!$A87,"") | CJ1: =IF('emission sources'!$A88<>"",'emission sources'!$A88,"") | CK1: =IF('emission sources'!$A89<>"",'emission sources'!$A89,"") | CL1: =IF('emission sources'!$A90<>"",'emission sources'!$A90,"") | CM1: =IF('emission sources'!$A91<>"",'emission sources'!$A91,"") | CN1: =IF('emission sources'!$A92<>"",'emission sources'!$A92,"") | CO1: =IF('emission sources'!$A93<>"",'emission sources'!$A93,"") | CP1: =IF('emission sources'!$A94<>"",'emission sources'!$A94,"") | CQ1: =IF('emission sources'!$A95<>"",'emission sources'!$A95,"") | CR1: =IF('emission sources'!$A96<>"",'emission sources'!$A96,"") | CS1: =IF('emission sources'!$A97<>"",'emission sources'!$A97,"") | CT1: =IF('emission sources'!$A98<>"",'emission sources'!$A98,"") | CU1: =IF('emission sources'!$A99<>"",'emission sources'!$A99,"") | CV1: =IF('emission sources'!$A100<>"",'emission sources'!$A100,"") | CW1: =IF('emission sources'!$A101<>"",'emission sources'!$A101,"") | CX1: =IF('emission sources'!$A102<>"",'emission sources'!$A102,"") | CY1: =IF('emission sources'!$A103<>"",'emission sources'!$A103,"") | CZ1: =IF('emission sources'!$A104<>"",'emission sources'!$A104,"") | DA1: =IF('emission sources'!$A105<>"",'emission sources'!$A105,"") | DB1: =IF('emission sources'!$A106<>"",'emission sources'!$A106,"") | DC1: =IF('emission sources'!$A107<>"",'emission sources'!$A107,"") | DD1: =IF('emission sources'!$A108<>"",'emission sources'!$A108,"") | DE1: =IF('emission sources'!$A109<>"",'emission sources'!$A109,"") | DF1: =IF('emission sources'!$A110<>"",'emission sources'!$A110,"") | DG1: =IF('emission sources'!$A111<>"",'emission sources'!$A111,"") | DH1: =IF('emission sources'!$A112<>"",'emission sources'!$A112,"") | DI1: =IF('emission sources'!$A113<>"",'emission sources'!$A113,"") | DJ1: =IF('emission sources'!$A114<>"",'emission sources'!$A114,"") | DK1: =IF('emission sources'!$A115<>"",'emission sources'!$A115,"") | DL1: =IF('emission sources'!$A116<>"",'emission sources'!$A116,"") | DM1: =IF('emission sources'!$A117<>"",'emission sources'!$A117,"") | DN1: =IF('emission sources'!$A118<>"",'emission sources'!$A118,"") | DO1: =IF('emission sources'!$A119<>"",'emission sources'!$A119,"") | DP1: =IF('emission sources'!$A120<>"",'emission sources'!$A120,"") | DQ1: =IF('emission sources'!$A121<>"",'emission sources'!$A121,"") | DR1: =IF('emission sources'!$A122<>"",'emission sources'!$A122,"") | DS1: =IF('emission sources'!$A123<>"",'emission sources'!$A123,"") | DT1: =IF('emission sources'!$A124<>"",'emission sources'!$A124,"") | DU1: =IF('emission sources'!$A125<>"",'emission sources'!$A125,"") | DV1: =IF('emission sources'!$A126<>"",'emission sources'!$A126,"") | DW1: =IF('emission sources'!$A127<>"",'emission sources'!$A127,"") | DX1: =IF('emission sources'!$A128<>"",'emission sources'!$A128,"") | DY1: =IF('emission sources'!$A129<>"",'emission sources'!$A129,"") | DZ1: =IF('emission sources'!$A130<>"",'emission sources'!$A130,"") | EA1: =IF('emission sources'!$A131<>"",'emission sources'!$A131,"") | EB1: =IF('emission sources'!$A132<>"",'emission sources'!$A132,"") | EC1: =IF('emission sources'!$A133<>"",'emission sources'!$A133,"") | ED1: =IF('emission sources'!$A134<>"",'emission sources'!$A134,"") | EE1: =IF('emission sources'!$A135<>"",'emission sources'!$A135,"") | EF1: =IF('emission sources'!$A136<>"",'emission sources'!$A136,"") | EG1: =IF('emission sources'!$A137<>"",'emission sources'!$A137,"") | EH1: =IF('emission sources'!$A138<>"",'emission sources'!$A138,"") | EI1: =IF('emission sources'!$A139<>"",'emission sources'!$A139,"") | EJ1: =IF('emission sources'!$A140<>"",'emission sources'!$A140,"") | EK1: =IF('emission sources'!$A141<>"",'emission sources'!$A141,"") | EL1: =IF('emission sources'!$A142<>"",'emission sources'!$A142,"") | EM1: =IF('emission sources'!$A143<>"",'emission sources'!$A143,"") | EN1: =IF('emission sources'!$A144<>"",'emission sources'!$A144,"") | EO1: =IF('emission sources'!$A145<>"",'emission sources'!$A145,"") | EP1: =IF('emission sources'!$A146<>"",'emission sources'!$A146,"") | EQ1: =IF('emission sources'!$A147<>"",'emission sources'!$A147,"") | ER1: =IF('emission sources'!$A148<>"",'emission sources'!$A148,"") | ES1: =IF('emission sources'!$A149<>"",'emission sources'!$A149,"") | ET1: =IF('emission sources'!$A150<>"",'emission sources'!$A150,"") | EU1: =IF('emission sources'!$A151<>"",'emission sources'!$A151,"") | EV1: =IF('emission sources'!$A152<>"",'emission sources'!$A152,"") | EW1: =IF('emission sources'!$A153<>"",'emission sources'!$A153,"") | EX1: =IF('emission sources'!$A154<>"",'emission sources'!$A154,"") | EY1: =IF('emission sources'!$A155<>"",'emission sources'!$A155,"") | EZ1: =IF('emission sources'!$A156<>"",'emission sources'!$A156,"") | FA1: =IF('emission sources'!$A157<>"",'emission sources'!$A157,"") | FB1: =IF('emission sources'!$A158<>"",'emission sources'!$A158,"") | FC1: =IF('emission sources'!$A159<>"",'emission sources'!$A159,"") | FD1: =IF('emission sources'!$A160<>"",'emission sources'!$A160,"") | FE1: =IF('emission sources'!$A161<>"",'emission sources'!$A161,"") | FF1: =IF('emission sources'!$A162<>"",'emission sources'!$A162,"") | FG1: =IF('emission sources'!$A163<>"",'emission sources'!$A163,"") | FH1: =IF('emission sources'!$A164<>"",'emission sources'!$A164,"") | FI1: =IF('emission sources'!$A165<>"",'emission sources'!$A165,"") | FJ1: =IF('emission sources'!$A166<>"",'emission sources'!$A166,"") | FK1: =IF('emission sources'!$A167<>"",'emission sources'!$A167,"") | FL1: =IF('emission sources'!$A168<>"",'emission sources'!$A168,"") | FM1: =IF('emission sources'!$A169<>"",'emission sources'!$A169,"") | FN1: =IF('emission sources'!$A170<>"",'emission sources'!$A170,"") | FO1: =IF('emission sources'!$A171<>"",'emission sources'!$A171,"") | FP1: =IF('emission sources'!$A172<>"",'emission sources'!$A172,"") | FQ1: =IF('emission sources'!$A173<>"",'emission sources'!$A173,"") | FR1: =IF('emission sources'!$A174<>"",'emission sources'!$A174,"") | FS1: =IF('emission sources'!$A175<>"",'emission sources'!$A175,"") | FT1: =IF('emission sources'!$A176<>"",'emission sources'!$A176,"") | FU1: =IF('emission sources'!$A177<>"",'emission sources'!$A177,"") | FV1: =IF('emission sources'!$A178<>"",'emission sources'!$A178,"") | FW1: =IF('emission sources'!$A179<>"",'emission sources'!$A179,"") | FX1: =IF('emission sources'!$A180<>"",'emission sources'!$A180,"") | FY1: =IF('emission sources'!$A181<>"",'emission sources'!$A181,"") | FZ1: =IF('emission sources'!$A182<>"",'emission sources'!$A182,"") | GA1: =IF('emission sources'!$A183<>"",'emission sources'!$A183,"") | GB1: =IF('emission sources'!$A184<>"",'emission sources'!$A184,"") | GC1: =IF('emission sources'!$A185<>"",'emission sources'!$A185,"") | GD1: =IF('emission sources'!$A186<>"",'emission sources'!$A186,"") | GE1: =IF('emission sources'!$A187<>"",'emission sources'!$A187,"") | GF1: =IF('emission sources'!$A188<>"",'emission sources'!$A188,"") | GG1: =IF('emission sources'!$A189<>"",'emission sources'!$A189,"") | GH1: =IF('emission sources'!$A190<>"",'emission sources'!$A190,"") | GI1: =IF('emission sources'!$A191<>"",'emission sources'!$A191,"") | GJ1: =IF('emission sources'!$A192<>"",'emission sources'!$A192,"") | GK1: =IF('emission sources'!$A193<>"",'emission sources'!$A193,"") | GL1: =IF('emission sources'!$A194<>"",'emission sources'!$A194,"") | GM1: =IF('emission sources'!$A195<>"",'emission sources'!$A195,"") | GN1: =IF('emission sources'!$A196<>"",'emission sources'!$A196,"") | GO1: =IF('emission sources'!$A197<>"",'emission sources'!$A197,"") | GP1: =IF('emission sources'!$A198<>"",'emission sources'!$A198,"") | GQ1: =IF('emission sources'!$A199<>"",'emission sources'!$A199,"") | GR1: =IF('emission sources'!$A200<>"",'emission sources'!$A200,"") | GS1: =IF('emission sources'!$A201<>"",'emission sources'!$A201,"") | GT1: =IF('emission sources'!$A202<>"",'emission sources'!$A202,"") | GU1: =IF('emission sources'!$A203<>"",'emission sources'!$A203,"") | GV1: =IF('emission sources'!$A204<>"",'emission sources'!$A204,"") | GW1: =IF('emission sources'!$A205<>"",'emission sources'!$A205,"") | GX1: =IF('emission sources'!$A206<>"",'emission sources'!$A206,"") | GY1: =IF('emission sources'!$A207<>"",'emission sources'!$A207,"") | GZ1: =IF('emission sources'!$A208<>"",'emission sources'!$A208,"") | HA1: =IF('emission sources'!$A209<>"",'emission sources'!$A209,"") | HB1: =IF('emission sources'!$A210<>"",'emission sources'!$A210,"") | HC1: =IF('emission sources'!$A211<>"",'emission sources'!$A211,"") | HD1: =IF('emission sources'!$A212<>"",'emission sources'!$A212,"") | HE1: =IF('emission sources'!$A213<>"",'emission sources'!$A213,"") | HF1: =IF('emission sources'!$A214<>"",'emission sources'!$A214,"") | HG1: =IF('emission sources'!$A215<>"",'emission sources'!$A215,"") | HH1: =IF('emission sources'!$A216<>"",'emission sources'!$A216,"") | HI1: =IF('emission sources'!$A217<>"",'emission sources'!$A217,"") | HJ1: =IF('emission sources'!$A218<>"",'emission sources'!$A218,"") | HK1: =IF('emission sources'!$A219<>"",'emission sources'!$A219,"") | HL1: =IF('emission sources'!$A220<>"",'emission sources'!$A220,"") | HM1: =IF('emission sources'!$A221<>"",'emission sources'!$A221,"") | HN1: =IF('emission sources'!$A222<>"",'emission sources'!$A222,"") | HO1: =IF('emission sources'!$A223<>"",'emission sources'!$A223,"") | HP1: =IF('emission sources'!$A224<>"",'emission sources'!$A224,"") | HQ1: =IF('emission sources'!$A225<>"",'emission sources'!$A225,"") | HR1: =IF('emission sources'!$A226<>"",'emission sources'!$A226,"") | HS1: =IF('emission sources'!$A227<>"",'emission sources'!$A227,"") | HT1: =IF('emission sources'!$A228<>"",'emission sources'!$A228,"") | HU1: =IF('emission sources'!$A229<>"",'emission sources'!$A229,"") | HV1: =IF('emission sources'!$A230<>"",'emission sources'!$A230,"") | HW1: =IF('emission sources'!$A231<>"",'emission sources'!$A231,"") | HX1: =IF('emission sources'!$A232<>"",'emission sources'!$A232,"") | HY1: =IF('emission sources'!$A233<>"",'emission sources'!$A233,"") | HZ1: =IF('emission sources'!$A234<>"",'emission sources'!$A234,"") | IA1: =IF('emission sources'!$A235<>"",'emission sources'!$A235,"") | IB1: =IF('emission sources'!$A236<>"",'emission sources'!$A236,"") | IC1: =IF('emission sources'!$A237<>"",'emission sources'!$A237,"") | ID1: =IF('emission sources'!$A238<>"",'emission sources'!$A238,"") | IE1: =IF('emission sources'!$A239<>"",'emission sources'!$A239,"") | IF1: =IF('emission sources'!$A240<>"",'emission sources'!$A240,"") | IG1: =IF('emission sources'!$A241<>"",'emission sources'!$A241,"") | IH1: =IF('emission sources'!$A242<>"",'emission sources'!$A242,"") | II1: =IF('emission sources'!$A243<>"",'emission sources'!$A243,"") | IJ1: =IF('emission sources'!$A244<>"",'emission sources'!$A244,"") | IK1: =IF('emission sources'!$A245<>"",'emission sources'!$A245,"") | IL1: =IF('emission sources'!$A246<>"",'emission sources'!$A246,"") | IM1: =IF('emission sources'!$A247<>"",'emission sources'!$A247,"") | IN1: =IF('emission sources'!$A248<>"",'emission sources'!$A248,"") | IO1: =IF('emission sources'!$A249<>"",'emission sources'!$A249,"") | IP1: =IF('emission sources'!$A250<>"",'emission sources'!$A250,"") | IQ1: =IF('emission sources'!$A251<>"",'emission sources'!$A251,"") | IR1: =IF('emission sources'!$A252<>"",'emission sources'!$A252,"") | IS1: =IF('emission sources'!$A253<>"",'emission sources'!$A253,"") | IT1: =IF('emission sources'!$A254<>"",'emission sources'!$A254,"") | IU1: =IF('emission sources'!$A255<>"",'emission sources'!$A255,"") | IV1: =IF('emission sources'!$A256<>"",'emission sources'!$A256,"") | IW1: =IF('emission sources'!$A257<>"",'emission sources'!$A257,"") | IX1: =IF('emission sources'!$A258<>"",'emission sources'!$A258,"") | IY1: =IF('emission sources'!$A259<>"",'emission sources'!$A259,"") | IZ1: =IF('emission sources'!$A260<>"",'emission sources'!$A260,"") | JA1: =IF('emission sources'!$A261<>"",'emission sources'!$A261,"") | JB1: =IF('emission sources'!$A262<>"",'emission sources'!$A262,"") | JC1: =IF('emission sources'!$A263<>"",'emission sources'!$A263,"") | JD1: =IF('emission sources'!$A264<>"",'emission sources'!$A264,"") | JE1: =IF('emission sources'!$A265<>"",'emission sources'!$A265,"") | JF1: =IF('emission sources'!$A266<>"",'emission sources'!$A266,"") | JG1: =IF('emission sources'!$A267<>"",'emission sources'!$A267,"") | JH1: =IF('emission sources'!$A268<>"",'emission sources'!$A268,"") | JI1: =IF('emission sources'!$A269<>"",'emission sources'!$A269,"") | JJ1: =IF('emission sources'!$A270<>"",'emission sources'!$A270,"") | JK1: =IF('emission sources'!$A271<>"",'emission sources'!$A271,"") | JL1: =IF('emission sources'!$A272<>"",'emission sources'!$A272,"") | JM1: =IF('emission sources'!$A273<>"",'emission sources'!$A273,"") | JN1: =IF('emission sources'!$A274<>"",'emission sources'!$A274,"") | JO1: =IF('emission sources'!$A275<>"",'emission sources'!$A275,"") | JP1: =IF('emission sources'!$A276<>"",'emission sources'!$A276,"") | JQ1: =IF('emission sources'!$A277<>"",'emission sources'!$A277,"") | JR1: =IF('emission sources'!$A278<>"",'emission sources'!$A278,"") | JS1: =IF('emission sources'!$A279<>"",'emission sources'!$A279,"") | JT1: =IF('emission sources'!$A280<>"",'emission sources'!$A280,"") | JU1: =IF('emission sources'!$A281<>"",'emission sources'!$A281,"") | JV1: =IF('emission sources'!$A282<>"",'emission sources'!$A282,"") | JW1: =IF('emission sources'!$A283<>"",'emission sources'!$A283,"") | JX1: =IF('emission sources'!$A284<>"",'emission sources'!$A284,"") | JY1: =IF('emission sources'!$A285<>"",'emission sources'!$A285,"") | JZ1: =IF('emission sources'!$A286<>"",'emission sources'!$A286,"") | KA1: =IF('emission sources'!$A287<>"",'emission sources'!$A287,"") | KB1: =IF('emission sources'!$A288<>"",'emission sources'!$A288,"")
A2: =IF(interventions!$A2<>"",interventions!$A2,"") -> solar_system1 | B2: y | C2: y
A3: =IF(interventions!$A3<>"",interventions!$A3,"") -> led_light1 | C3: y
A4: =IF(interventions!$A4<>"",interventions!$A4,"") -> energy_efficient_fridge1 | B4: y
A5: =IF(interventions!$A5<>"",interventions!$A5,"") -> energy_efficient_fridge_multi5 | B5: y
A6: =IF(interventions!$A6<>"",interventions!$A6,"") -> laundry_machine | B6: y
A7: =IF(interventions!$A7<>"",interventions!$A7,"") -> energy_efficient_ac_multi1 | I7: Y
A8: =IF(interventions!$A8<>"",interventions!$A8,"") -> energy_efficient_ac_multi5 | I8: Y
A9: =IF(interventions!$A9<>"",interventions!$A9,"") -> energy_efficient_ac_multi10 | I9: Y
A10: =IF(interventions!$A10<>"",interventions!$A10,"") -> tree_planting_multi100 | B10: y | C10: y | D10: y | E10: y | F10: y | G10: y | H10: y | I10: y | J10: y | K10: y | L10: y
A11: =IF(interventions!$A11<>"",interventions!$A11,"") -> tree_planting_multi200 | B11: y | C11: y | D11: y | E11: y | F11: y | G11: y | H11: y | I11: y | J11: y | K11: y | L11: y
A12: =IF(interventions!$A12<>"",interventions!$A12,"") -> waste_segregation | K12: y
A13: =IF(interventions!$A13<>"",interventions!$A13,"") -> staff_training_awareness | B13: y | C13: y | D13: y | E13: y | F13: y | G13: y | H13: y | I13: y | J13: y | K13: y | L13: y
A14: =IF(interventions!$A14<>"",interventions!$A14,"")
A15: =IF(interventions!$A15<>"",interventions!$A15,"")
A16: =IF(interventions!$A16<>"",interventions!$A16,"")
A17: =IF(interventions!$A17<>"",interventions!$A17,"")
A18: =IF(interventions!$A18<>"",interventions!$A18,"")
A19: =IF(interventions!$A19<>"",interventions!$A19,"")
A20: =IF(interventions!$A20<>"",interventions!$A20,"")
A21: =IF(interventions!$A21<>"",interventions!$A21,"")
A22: =IF(interventions!$A22<>"",interventions!$A22,"")
A23: =IF(interventions!$A23<>"",interventions!$A23,"")
A24: =IF(interventions!$A24<>"",interventions!$A24,"")
A25: =IF(interventions!$A25<>"",interventions!$A25,"")
... A296: =IF(interventions!$A296<>"",interventions!$A296,"")

Sheet effect sizes
